
  [Previous line repeated 2 more times]
  File "c:\users\a249614\dbt1\lib\site-packages\dbt_common\utils\connection.py", line 35, in connection_exception_retry
    raise ConnectionError("External connection exception occurred: " + str(exc))
dbt_common.exceptions.connection.ConnectionError: External connection exception occurred: HTTPSConnectionPool(host='hub.getdbt.com', port=443): Max retries exceeded with url: /api/v1/index.json (Caused by SSLError(SSLCertVerificationError(1, '[SSL: CERTIFICATE_VERIFY_FAILED] certificate verify failed: unable to get local issuer certificate (_ssl.c:1125)')))
